<?xml version="1.0" ?>
<robot name='krever' xmlns:xacro="http://ros.org/wiki/xacro">

  <xacro:include filename="inertial_macros.xacro"/>

  <!-- Robot's base properties -->
  <xacro:property name="base_length" value="0.3"/>
  <xacro:property name="base_width" value="0.3"/>
  <xacro:property name="base_height" value="0.15"/>

  <!-- Robot's wheel properties -->
  <xacro:property name="wheel_radius" value="0.05"/>
  <xacro:property name="wheel_height" value="0.03"/>
  <xacro:property name="wheel_mass" value="0.15"/>

  <!-- Distance between centre of wheel and robot base -->
  <xacro:property name="wheel_zoff" value="0.33"/>

  <link name="base_footprint"/> 	

   <joint name="base_joint" type="fixed">
     <parent link="base_footprint"/>
     <child link="base_link"/>
     <origin xyz="0 0 0" rpy="0 0 0"/>
   </joint>
	
  <!-- Robot base chasis-->
  <link name="base_link">
      <visual>
          <geometry>
              <box size="0.3 0.3 0.15"/>
          </geometry>
          <origin xyz="0 0 0.105" rpy="0 0 0"/>
          <material name="red"/>
      </visual>

      <collision>
          <geometry>
              <box size="0.3 0.3 0.15"/>
          </geometry>
          <origin xyz="0 0 0.105" rpy="0 0 0"/>
          <material name="red"/>
      </collision>

    

      <!-- Rplidar base -->
      <visual name="rplidar_base_visual">
        <origin xyz="0 0 0.175" rpy="0 0 ${-pi/2}"/>
          <geometry>
            <mesh filename="package://krever_description/meshes/rplidar_base.dae"/>
          </geometry>
        </visual>
      <collision name="rplidar_base_collision">
        <origin xyz="0 0 0.175" rpy="0 0 ${-pi/2}"/>
        <geometry>
          <box size="0.11 0.072 0.035"/>
        </geometry>
      </collision>


    <xacro:box_inertia mass="0.864" length="${base_length}" width="${base_width}" height="${base_height}">
      <origin xyz="0 0 0.175" rpy="0 0 0"/>
    </xacro:box_inertia>
  </link>

  <!-- Left wheel -->
  <link name="left_wheel">
    <visual>
        <geometry>
            <cylinder radius="0.05" length="0.03"/>
        </geometry>
        <origin xyz="0 0 0" rpy="1.57 0 0"/>
        <material name="green"/>
    </visual>
    <collision>
        <geometry>
            <cylinder radius="0.05" length="0.03"/>
        </geometry>
        <origin xyz="0 0 0" rpy="1.57 0 0"/>
        <material name="green"/>
    </collision>

    <xacro:cylinder_inertia mass="${wheel_mass}" length="${wheel_height}" radius="${wheel_radius}">
      <origin xyz="0 0 0" rpy="0 0 0"/>
    </xacro:cylinder_inertia>
  </link>

  <joint name="left_wheel_joint" type="continuous">
    <parent link="base_link"/>
    <child link="left_wheel"/>
    <origin xyz="0 0.165 0.05" rpy="0 0 0"/>
    <axis xyz="0 1 0"/>
  </joint>

  <!-- Right wheel -->
  <link name="right_wheel">
    <visual>
        <geometry>
            <cylinder radius="0.05" length="0.03"/>
        </geometry>
        <origin xyz="0 0 0" rpy="1.57 0 0"/>
        <material name="green"/>
    </visual>
    <collision>
        <geometry>
            <cylinder radius="0.05" length="0.03"/>
        </geometry>
        <origin xyz="0 0 0" rpy="1.57 0 0"/>
        <material name="green"/>
    </collision>

    <xacro:cylinder_inertia mass="${wheel_mass}" length="${wheel_height}" radius="${wheel_radius}">
      <origin xyz="0 0 0" rpy="0 0 0"/>
    </xacro:cylinder_inertia>
  </link>

  <joint name="right_wheel_joint" type="continuous">
    <parent link="base_link"/>
    <child link="right_wheel"/>
    <origin xyz="0 -0.165 0.05" rpy="0 0 0"/>
    <axis xyz="0 1 0"/>
  </joint>

  <!-- Caster wheel -->
  <link name="caster_wheel">
    <visual>
      <geometry>
        <mesh filename="package://krever_description/meshes/caster_wheel.dae"/>
      </geometry>
    </visual>
    <collision>
      <origin xyz="0 0 0" rpy="0 0 ${pi/2}"/>
      <geometry>
        <sphere radius="0.0175"/>
      </geometry>
    </collision>

    <xacro:sphere_inertia mass="0.033" radius="0.025">
      <origin xyz="0 0 0" rpy="0 0 0"/>
    </xacro:sphere_inertia>
  </link>

  <joint name="caster_wheel_joint" type="fixed">
    <parent link="base_link"/>
    <child link="caster_wheel"/>
    <origin xyz="0.1375 0 0.0175" rpy="0 0 ${pi/2}"/>
  </joint>

  <gazebo reference="caster_wheel">
    <mu1 value="0.001"/>
    <mu2 value="0.001"/>
  </gazebo>


  <!-- Caster wheel2 -->
  <link name="caster_wheel2">
    <visual>
      <geometry>
        <mesh filename="package://krever_description/meshes/caster_wheel.dae"/>
      </geometry>
    </visual>
    <collision>
      <origin xyz="0 0 0" rpy="0 0 ${pi/2}"/>
      <geometry>
        <sphere radius="0.0175"/>
      </geometry>
    </collision>

    <xacro:sphere_inertia mass="0.033" radius="0.025">
      <origin xyz="0 0 0" rpy="0 0 0"/>
    </xacro:sphere_inertia>
  </link>

  <joint name="caster_wheel_joint2" type="fixed">
    <parent link="base_link"/>
    <child link="caster_wheel2"/>
    <origin xyz="-0.1375 0 0.0175" rpy="0 0 ${pi/2}"/>
  </joint>

  <gazebo reference="caster_wheel2">
    <mu1 value="0.001"/>
    <mu2 value="0.001"/>
  </gazebo>


  <gazebo reference="left_wheel">
    <mu1 value="1.16"/>
    <mu2 value="1.16"/>
  </gazebo>

  <gazebo reference="right_wheel">
    <mu1 value="1.16"/>
    <mu2 value="1.16"/>
  </gazebo>

  <!--colors-->
    <material name="green">
        <color rgba="0 1 0 1"/>
    </material>

    <material name="blue">
        <color rgba="0 0 0.7 1"/>
    </material>

    <material name="red">
        <color rgba="0.7 0 0 1"/>
    </material>

    !--supporint rod-->
    <link name="support_rod">
        <visual>
            <geometry>
                <box size="0.03 0.05 0.5" />
            </geometry>
            <material name="LightGrey">
                <color rgba="0.7 0.7 0.7 1.0"/>
            </material>
        </visual>
        <collision>
            <geometry>
                <box size="0.03 0.05 0.5" />
            </geometry>
        </collision>

        <inertial>
            <origin xyz="0.0 0.0 0.0" rpy="0.0 0.0 0.0"/>
            <mass value="5"/>
            <inertia ixx="0.105" ixy="0.0" ixz="0.0" iyy="0.104" iyz="0.0" izz="0.0014"/>
        </inertial>
        

        
    </link>

    <joint name="base_suppot_joint" type="fixed">
        <origin xyz="-0.135 0. 0.425" rpy="0.0 0.0 0.0"/>
        <parent link="base_link"/>
        <child link="support_rod"/>
        <limit lower="0.0" upper="0.0" effort="0.0" velocity="0.0"/>
    </joint>


<!--u1-->
    <link name="center_rod">
        <visual>
            <geometry>
                <box size="0.2 0.05 0.02" />
            </geometry>
            <material name="black">
                <color rgba="0 0 0 1"/>
            </material>
        </visual>
        <collision>
            <geometry>
                <box size="0.2 0.05 0.02" />
            </geometry>
        </collision>

        <inertial>
            <origin xyz="0.0 0.0 0.0" rpy="0.0 0.0 0.0"/>
            <mass value="2"/>
            <inertia ixx="0.002" ixy="0.0" ixz="0.0" iyy="0.027" iyz="0.0" izz="0.028"/>
        </inertial>
        

    </link>

    <joint name="center_rod_joint" type="fixed">
        <origin xyz="0 0 0.26" rpy="0 0 1.57"/>
        <parent link="support_rod"/>
        <child link="center_rod"/>
        <limit lower="0.0" upper="0.0" effort="0.0" velocity="0.0"/>
    </joint>

<!--u2-->
    
    <link name="left_rod">
        <visual>
            <geometry>
                <box size="0.3 0.05 0.02" />
            </geometry>
            <material name="black">
                <color rgba="0 0 0 1"/>
            </material>
        </visual>
        <collision>
            <geometry>
                <box size="0.3 0.05 0.02" />
            </geometry>
        </collision>

        <inertial>
            <origin xyz="0.0 0.0 0.0" rpy="0.0 0.0 0.0"/>
            <mass value="2"/>
            <inertia ixx="0.002" ixy="0.0" ixz="0.0" iyy="0.06" iyz="0.0" izz="0.061"/>
        </inertial>
        

    </link>

    <joint name="left_rod_joint" type="fixed">
        <origin xyz="0.125 0.125 0.26" rpy="0.0 0.0 0"/>
        <parent link="support_rod"/>
        <child link="left_rod"/>
        <limit lower="0.0" upper="0.0" effort="0.0" velocity="0.0"/>
    </joint>    


<!--u3-->
    
    <link name="right_rod">
        <visual>
            <geometry>
                <box size="0.3 0.05 0.02" />
            </geometry>
            <material name="black">
                <color rgba="0 0 0 1"/>
            </material>
        </visual>
        <collision>
            <geometry>
                <box size="0.3 0.05 0.02" />
            </geometry>
        </collision>

        <inertial>
            <origin xyz="0.0 0.0 0.0" rpy="0.0 0.0 0.0"/>
            <mass value="2"/>
            <inertia ixx="0.002" ixy="0.0" ixz="0.0" iyy="0.06" iyz="0.0" izz="0.061"/>
        </inertial>
    </link>

    <joint name="right_rod_joint" type="fixed">
        <origin xyz="0.125 -0.125 0.26" rpy="0.0 0.0 0"/>
        <parent link="support_rod"/>
        <child link="right_rod"/>
        <limit lower="0.0" upper="0.0" effort="0.0" velocity="0.0"/>
    </joint>

<!--tray-->
    <link name="tray">
        <visual>
            <origin xyz="0.0 0.0 0.0" rpy="0.0 0.0 0.0"/>
            <geometry>
                <box size="0.3 0.3 0.01"/>
            </geometry>
            <material name="white">
                <color rgba="1.0 1.0 1.0 1.0"/>
            </material>
        </visual>
        <collision>
            <origin xyz="0.0 0.0 0.0" rpy="0.0 0.0 0.0"/>
            <geometry>
                <box size="0.6 0.6 0.01"/>
            </geometry>
        </collision>

        <inertial>
            <origin xyz="0.0 0.0 0.0" rpy="0.0 0.0 0.0"/>
            <mass value="5"/>
            <inertia ixx="0.154" ixy="0.0" ixz="0.0" iyy="0.154" iyz="0.0" izz="0.3"/>
        </inertial>
        
    </link>

    <joint name="tray_joint" type="fixed">
        <origin xyz="0.135 0.0 -0.18" rpy="0.0 0.0 0.0"/>
        <parent link="support_rod"/>
        <child link="tray"/>
        <limit lower="0.0" upper="0.0" effort="0.0" velocity="0.0"/>
    </joint>


</robot>
